Workbook

Sheet 🏠 PORTADA
B4: IMPULSO · Máster en Dirección de Proyectos · Universidad de Valladolid · Álvar del Prado Suárez · 2026
B6: ='⚙️ SUPUESTOS'!C28 -> 203 | C6: ='📊 PANEL'!V2&" / "&'📊 PANEL'!V3&" / "&'📊 PANEL'!V4 -> 67 / 68 / 68
B7: portales certificados | C7: Fases 1 / 2 / 3
B9: INSTRUCCIONES DE USO
B10: 1. Introduce o edita los datos de cada edificio en la hoja INVENTARIO (punto de entrada único). 2. El RANKING, las fases y el PANEL se recalculan automáticamente. 3. Ajusta los pesos del AHP y los demás parámetros en la hoja SUPUESTOS. 4. Selecciona el ámbito (barrio) en el desplegable superior. 5. Para visualizarlo sobre el mapa, carga este libro en la herramienta IMPULSO (botón 📂 Cargar Excel).
B16: CRITERIOS DEL MODELO AHP (Saaty, 1994 · RC = 0,053)
B17: C1 · Consumo EP individual | C17: 55% | D17: Energía primaria kWh/m²·año (certificado JCyL), min–max sobre el ranking
B18: C2 · Vulnerabilidad económica | C18: 22% | D18: 40%·paro + 40% · (1−renta) + 20%·alquiler (INE, 2021 + ADRH, 2023)
B19: C3 · Vulnerabilidad social | C19: 14% | D19: % población sin estudios superiores (INE, 2021, invertido)
B20: C4 · Vuln. demográfica (envejecimiento) | C20: 9% | D20: % población >64 años (Padrón, INE, 2023)
B22: Índice Pk = 0,55·C1n + 0,22·C2n + 0,14·C3n + 0,09·C4n → Ranking 1–203 → 3 fases
B24: ¿POR QUÉ ESTAS ACTUACIONES?
B25: La intervención propuesta se asigna en función de la calificación energética del edificio: cuanto peor es la calificación de partida, más profunda es la actuación recomendada. Esta lógica es coherente con las exigencias del programa estatal de rehabilitación (RD 853/2021), que condiciona las ayudas a una reducción mínima del 30 % del consumo de energía primaria no renovable.
B27: Cal. G / F | D27: Renovación integral: SATE integral + cubierta + carpinterías triple + aerotermia + instalación fotovoltaica.
B28: Cal. E | D28: Envolvente parcial: SATE fachada + carpinterías doble + instalación fotovoltaica.
B29: Cal. D | D29: Mantenimiento de envolvente + instalación fotovoltaica en cubierta.
B30: Accesibilidad | D30: No hay dato por edificio de si ya tiene ascensor: se marca "valorar ascensor (verificar)" solo en 4+ plantas, a confirmar en campo.
B32: ENERGÍA SOLAR:
B33: Estimación del potencial solar fotovoltaico por cubierta: kWp a partir de la superficie disponible, producción según la radiación del IGN y ahorro económico asociado, con parámetros calibrados contra el visor solar del IGN (desviación aproximada del ±5%). La amortización varía según la cubierta y la columna se colorea automáticamente (verde = mejor retorno; rojo = peor). Cifras orientativas, a contrastar en proyecto.
B36: LEYENDA DE COLORES
B37: Calificación energética: | E37: G | F37: F | G37: E | H37: D
B38: Fases: | E38: F1 | F38: F2 | G38: F3
B39: Azul = editable · Verde = enlace entre hojas · Negro = fórmula · Barras/escalas = magnitud relativa
B41: Barrio (contorno del mapa) ▼
B43: Se lee al pulsar “Cargar Excel” en el mapa) | D43: Pajarillos Bajos
O130: 41.650674
O160: 41.650743 | P160: -4.708165

Sheet 📇 INVENTARIO
A1: 📇 INVENTARIO DE EDIFICIOS — entrada de datos
B2: ⬇ Añada un edificio para calcular el RANKING.
A3: # | B3: Dirección | C3: Ref. catastral | D3: Sección | E3: Certificado | F3: Cal. | G3: EP kWh/m² | H3: CO₂ kg/m² | I3: Dcal kWh/m² | J3: Año | K3: Plantas | L3: Sup.cub m² | M3: Sup.fach m² (auto) | N3: Rad.IGN | O3: Lat | P3: Lon
A4: =IF($B4="","",COUNTA($B$4:B4)) -> 1 | B4: C/ Salud, 19 | C4: 7625401UM5172F | D4: 4718606026 | E4: Sí | F4: G | G4: 713 | H4: 151 | I4: 368.8 | J4: 1958 | K4: 5 | L4: 330.5 | M4: =IF(OR($K4="",$L4=""),"",ROUND('⚙️ SUPUESTOS'!$C$14*'⚙️ SUPUESTOS'!$C$18*SQRT($L4)*$K4,0)) -> 1227 | N4: 1373 | O4: 41.649797 | P4: -4.710882
A5: =IF($B5="","",COUNTA($B$4:B5)) -> 2 | B5: C/ Pavo Real, 21 | C5: 7625404UM5172F | D5: 4718606026 | E5: Sí | F5: G | G5: 630 | H5: 107 | I5: 178.9 | J5: 1965 | K5: 3 | L5: 96.2 | M5: =IF(OR($K5="",$L5=""),"",ROUND('⚙️ SUPUESTOS'!$C$14*'⚙️ SUPUESTOS'!$C$18*SQRT($L5)*$K5,0)) -> 397 | N5: 1477 | O5: 41.64943 | P5: -4.71056
A6: =IF($B6="","",COUNTA($B$4:B6)) -> 3 | B6: C/ Salud, 17 | C6: 7625401UM5172F | D6: 4718606026 | E6: Sí | F6: G | G6: 528 | H6: 90 | I6: 211 | J6: 1958 | K6: 5 | L6: 330.5 | M6: =IF(OR($K6="",$L6=""),"",ROUND('⚙️ SUPUESTOS'!$C$14*'⚙️ SUPUESTOS'!$C$18*SQRT($L6)*$K6,0)) -> 1227 | N6: 1373 | O6: 41.649497 | P6: -4.711089
A7: =IF($B7="","",COUNTA($B$4:B7)) -> 4 | B7: C/ Halcón, 2 | C7: 7925705UM5172F | D7: 4718606023 | E7: Sí | F7: G | G7: 646 | H7: 110 | I7: 218.2 | J7: 1965 | K7: 3 | L7: 102.1 | M7: =IF(OR($K7="",$L7=""),"",ROUND('⚙️ SUPUESTOS'!$C$14*'⚙️ SUPUESTOS'!$C$18*SQRT($L7)*$K7,0)) -> 409 | N7: 1380 | O7: 41.64986 | P7: -4.70842
A8: =IF($B8="","",COUNTA($B$4:B8)) -> 5 | B8: C/ Rincón del Esgueva, 13 | C8: 7726409UM5172F | D8: 4718606023 | E8: Sí | F8: G | G8: 634 | H8: 134 | I8: 334.2 | J8: 1936 | K8: 1 | L8: 53.6 | M8: =IF(OR($K8="",$L8=""),"",ROUND('⚙️ SUPUESTOS'!$C$14*'⚙️ SUPUESTOS'!$C$18*SQRT($L8)*$K8,0)) -> 99 | N8: 1515 | O8: 41.65012 | P8: -4.70963
A9: =IF($B9="","",COUNTA($B$4:B9)) -> 6 | B9: C/ Calandria, 4 | C9: 7925710UM5172F | D9: 4718606023 | E9: Sí | F9: G | G9: 632 | H9: 134 | I9: 251.9 | J9: 1965 | K9: 3 | L9: 101.6 | M9: =IF(OR($K9="",$L9=""),"",ROUND('⚙️ SUPUESTOS'!$C$14*'⚙️ SUPUESTOS'!$C$18*SQRT($L9)*$K9,0)) -> 408 | N9: 1366 | O9: 41.64975 | P9: -4.70784
A10: =IF($B10="","",COUNTA($B$4:B10)) -> 7 | B10: C/ Pavo Real, 17 | C10: 7625406UM5172F | D10: 4718606026 | E10: Sí | F10: G | G10: 464 | H10: 118 | I10: 180.2 | J10: 1965 | K10: 3 | L10: 95.1 | M10: =IF(OR($K10="",$L10=""),"",ROUND('⚙️ SUPUESTOS'!$C$14*'⚙️ SUPUESTOS'!$C$18*SQRT($L10)*$K10,0)) -> 395 | N10: 1467 | O10: 41.64922 | P10: -4.71073
A11: =IF($B11="","",COUNTA($B$4:B11)) -> 8 | B11: C/ Marabú, 1 | C11: 7924213UM5172D | D11: 4718606024 | E11: Sí | F11: G | G11: 724 | H11: 148 | I11: 374.5 | J11: 1965 | K11: 3 | L11: 97.4 | M11: =IF(OR($K11="",$L11=""),"",ROUND('⚙️ SUPUESTOS'!$C$14*'⚙️ SUPUESTOS'!$C$18*SQRT($L11)*$K11,0)) -> 400 | N11: 1394 | O11: 41.64934 | P11: -4.70757
A12: =IF($B12="","",COUNTA($B$4:B12)) -> 9 | B12: C/ Águila, 20 | C12: 7824519UM5172D | D12: 4718606026 | E12: Sí | F12: G | G12: 461 | H12: 79 | I12: 155.4 | J12: 1965 | K12: 3 | L12: 110.7 | M12: =IF(OR($K12="",$L12=""),"",ROUND('⚙️ SUPUESTOS'!$C$14*'⚙️ SUPUESTOS'!$C$18*SQRT($L12)*$K12,0)) -> 426 | N12: 1517 | O12: 41.64889 | P12: -4.70906
A13: =IF($B13="","",COUNTA($B$4:B13)) -> 10 | B13: C/ Albatros, 1 | C13: 7724226UM5172D | D13: 4718606026 | E13: Sí | F13: G | G13: 454 | H13: 96 | I13: 173.2 | J13: 1965 | K13: 3 | L13: 95.5 | M13: =IF(OR($K13="",$L13=""),"",ROUND('⚙️ SUPUESTOS'!$C$14*'⚙️ SUPUESTOS'!$C$18*SQRT($L13)*$K13,0)) -> 396 | N13: 1431 | O13: 41.64887 | P13: -4.71047
A14: =IF($B14="","",COUNTA($B$4:B14)) -> 11 | B14: C/ Papagayo, 6 | C14: 7825411UM5172F | D14: 4718606023 | E14: Sí | F14: G | G14: 589 | H14: 100 | I14: 242.3 | J14: 1965 | K14: 3 | L14: 100.8 | M14: =IF(OR($K14="",$L14=""),"",ROUND('⚙️ SUPUESTOS'!$C$14*'⚙️ SUPUESTOS'!$C$18*SQRT($L14)*$K14,0)) -> 407 | N14: 1399 | O14: 41.64956 | P14: -4.70818
A15: =IF($B15="","",COUNTA($B$4:B15)) -> 12 | B15: C/ Villabáñez, 18 | C15: 7824502UM5172D | D15: 4718606026 | E15: Sí | F15: G | G15: 442 | H15: 93 | I15: 200 | J15: 1965 | K15: 3 | L15: 113.4 | M15: =IF(OR($K15="",$L15=""),"",ROUND('⚙️ SUPUESTOS'!$C$14*'⚙️ SUPUESTOS'!$C$18*SQRT($L15)*$K15,0)) -> 431 | N15: 1421 | O15: 41.64896 | P15: -4.70864
... A206: =IF($B206="","",COUNTA($B$4:B206)) -> 203 | B206: C/ Juan Carlos I, 87 | C206: 7922508UM5172B | D206: 4718606025 | E206: Sí | F206: E | G206: 174 | H206: 37 | I206: 65.2 | J206: 1970 | K206: 5 | L206: 417 | M206: =IF(OR($K206="",$L206=""),"",ROUND('⚙️ SUPUESTOS'!$C$14*'⚙️ SUPUESTOS'!$C$18*SQRT($L206)*$K206,0)) -> 1378 | N206: 1519 | O206: 41.64665 | P206: -4.70723
A207: =IF($B207="","",COUNTA($B$4:B207))
A208: =IF($B208="","",COUNTA($B$4:B208))
A209: =IF($B209="","",COUNTA($B$4:B209))
A210: =IF($B210="","",COUNTA($B$4:B210))
A211: =IF($B211="","",COUNTA($B$4:B211))
A212: =IF($B212="","",COUNTA($B$4:B212))
A213: =IF($B213="","",COUNTA($B$4:B213))
A214: =IF($B214="","",COUNTA($B$4:B214))
A215: =IF($B215="","",COUNTA($B$4:B215))
A216: =IF($B216="","",COUNTA($B$4:B216))
A217: =IF($B217="","",COUNTA($B$4:B217))
A218: =IF($B218="","",COUNTA($B$4:B218))
... A266: =IF($B266="","",COUNTA($B$4:B266))
A268: =IF($B268="","",COUNTA($B$4:B268)) -> 204 | B268: C/ Villabáñez, 3 | C268: 7825710UM5172F | E268: No | F268: ? | G268: 0 | H268: 0 | J268: 1963 | K268: 3 | L268: 180 | M268: =IF(OR($K268="",$L268=""),"",ROUND('⚙️ SUPUESTOS'!$C$14*'⚙️ SUPUESTOS'!$C$18*SQRT($L268)*$K268,0)) -> 543 | O268: 41.64994 | P268: -4.71035
A269: =IF($B269="","",COUNTA($B$4:B269)) -> 205 | B269: C/ Cigüeña, 32 | C269: 7923013UM5172D | E269: No | F269: ? | G269: 0 | H269: 0 | J269: 1962 | K269: 3 | L269: 395 | M269: =IF(OR($K269="",$L269=""),"",ROUND('⚙️ SUPUESTOS'!$C$14*'⚙️ SUPUESTOS'!$C$18*SQRT($L269)*$K269,0)) -> 805 | O269: 41.64837 | P269: -4.70852
A270: =IF($B270="","",COUNTA($B$4:B270)) -> 206 | B270: C/ Villabáñez, 13 | C270: 7825418UM5172F | E270: No | F270: ? | G270: 0 | H270: 0 | J270: 1965 | K270: 5 | L270: 722 | M270: =IF(OR($K270="",$L270=""),"",ROUND('⚙️ SUPUESTOS'!$C$14*'⚙️ SUPUESTOS'!$C$18*SQRT($L270)*$K270,0)) -> 1814 | O270: 41.64955 | P270: -4.7092
A271: =IF($B271="","",COUNTA($B$4:B271)) -> 207 | B271: C/ Gavilán, 2 | C271: 7825403UM5172F | E271: No | F271: ? | G271: 0 | H271: 0 | J271: 1965 | K271: 3 | L271: 101 | M271: =IF(OR($K271="",$L271=""),"",ROUND('⚙️ SUPUESTOS'!$C$14*'⚙️ SUPUESTOS'!$C$18*SQRT($L271)*$K271,0)) -> 407 | O271: 41.64962 | P271: -4.7089
A272: =IF($B272="","",COUNTA($B$4:B272)) -> 208 | B272: C/ Cigüeña, 49 | C272: 7825414UM5172F | E272: No | F272: ? | G272: 0 | H272: 0 | J272: 1965 | K272: 3 | L272: 98 | M272: =IF(OR($K272="",$L272=""),"",ROUND('⚙️ SUPUESTOS'!$C$14*'⚙️ SUPUESTOS'!$C$18*SQRT($L272)*$K272,0)) -> 401 | O272: 41.64915 | P272: -4.70828
A273: =IF($B273="","",COUNTA($B$4:B273)) -> 209 | B273: C/ Halcón, 4 | C273: 7925706UM5172F | E273: No | F273: ? | G273: 0 | H273: 0 | J273: 1965 | K273: 3 | L273: 102 | M273: =IF(OR($K273="",$L273=""),"",ROUND('⚙️ SUPUESTOS'!$C$14*'⚙️ SUPUESTOS'!$C$18*SQRT($L273)*$K273,0)) -> 409 | O273: 41.64993 | P273: -4.70821
A274: =IF($B274="","",COUNTA($B$4:B274)) -> 210 | B274: C/ Gorrión, 2 | C274: 7925704UM5172F | E274: No | F274: ? | G274: 0 | H274: 0 | J274: 1965 | K274: 3 | L274: 102 | M274: =IF(OR($K274="",$L274=""),"",ROUND('⚙️ SUPUESTOS'!$C$14*'⚙️ SUPUESTOS'!$C$18*SQRT($L274)*$K274,0)) -> 409 | O274: 41.64994 | P274: -4.70865
A275: =IF($B275="","",COUNTA($B$4:B275)) -> 211 | B275: C/ Cisne, 2 | C275: 7925701UM5172F | E275: No | F275: ? | G275: 0 | H275: 0 | J275: 1965 | K275: 3 | L275: 98 | M275: =IF(OR($K275="",$L275=""),"",ROUND('⚙️ SUPUESTOS'!$C$14*'⚙️ SUPUESTOS'!$C$18*SQRT($L275)*$K275,0)) -> 401 | O275: 41.65004 | P275: -4.70881
A276: =IF($B276="","",COUNTA($B$4:B276)) -> 212 | B276: C/ Calandria, 2 | C276: 7925709UM5172F | E276: No | F276: ? | G276: 0 | H276: 0 | J276: 1965 | K276: 3 | L276: 100 | M276: =IF(OR($K276="",$L276=""),"",ROUND('⚙️ SUPUESTOS'!$C$14*'⚙️ SUPUESTOS'!$C$18*SQRT($L276)*$K276,0)) -> 405 | O276: 41.64969 | P276: -4.70803
A277: =IF($B277="","",COUNTA($B$4:B277)) -> 213 | B277: C/ Villabáñez, 10 | C277: 7724202UM5172D | E277: No | F277: ? | G277: 0 | H277: 0 | J277: 1965 | K277: 3 | L277: 117 | M277: =IF(OR($K277="",$L277=""),"",ROUND('⚙️ SUPUESTOS'!$C$14*'⚙️ SUPUESTOS'!$C$18*SQRT($L277)*$K277,0)) -> 438 | O277: 41.64945 | P277: -4.7098
A278: =IF($B278="","",COUNTA($B$4:B278)) -> 214 | B278: C/ Cuclillo, 1 | C278: 7724211UM5172D | E278: No | F278: ? | G278: 0 | H278: 0 | J278: 1965 | K278: 3 | L278: 107 | M278: =IF(OR($K278="",$L278=""),"",ROUND('⚙️ SUPUESTOS'!$C$14*'⚙️ SUPUESTOS'!$C$18*SQRT($L278)*$K278,0)) -> 419 | O278: 41.64893 | P278: -4.7095
...

Sheet 📋 RANKING
A1: IDENTIFICACIÓN Y PRIORIDAD | F1: CERT. ENERGÉTICO — JCyL 2026 | K1: CRITERIOS AHP (0–1) | P1: SOCIOECONÓMICO (sección) | S1: CATASTRO ⚠ | T1: ACTUACIÓN PROPUESTA | V1: ☀️ SOLAR FV — IGN + cálculo paramétrico ⚠ | AG1: COORDENADAS
A2: # | B2: Fase | C2: Dirección | D2: Ref. catastral | E2: Sección | F2: Cal. EP | G2: EP kWh/m² | H2: CO₂ kg/m² | I2: Demanda calef. kWh/m² | J2: Año constr. | K2: C1n | L2: C2n | M2: C3n | N2: C4n | O2: Índice Pk | P2: Paro % | Q2: Renta €/hog | R2: Edad>64 % | S2: Plantas ⚠ | T2: Actuación energética (según calificación) | U2: Accesibilidad | V2: Sup. cub. m² | W2: kWp | X2: Rad. IGN kWh/m²·a | Y2: Producción kWh/año | Z2: Inversión € (sin subv.) | AA2: Ahorro €/año | AB2: Ahorro consumo €/año ⚡ | AC2: Ahorro compensación €/año 🔌 | AD2: Ahorro acumulado vida útil 25 años € | AE2: Amort. años | AF2: FV recomendada | AG2: Lat | AH2: Lon
A3: =IF($C3="","",RANK(O3,$O$3:$O$265,0)+COUNTIF($O$3:O3,O3)-1) -> 1 | B3: =IF($C3="","",IF(A3<='⚙️ SUPUESTOS'!$C$29,"Fase 1",IF(A3<='⚙️ SUPUESTOS'!$C$30,"Fase 2","Fase 3"))) -> Fase 1 | C3: =IF('📇 INVENTARIO'!B4="","",'📇 INVENTARIO'!B4) -> C/ Salud, 19 | D3: =IF('📇 INVENTARIO'!C4="","",'📇 INVENTARIO'!C4) -> 7625401UM5172F | E3: =IF('📇 INVENTARIO'!D4="","",'📇 INVENTARIO'!D4) -> 4718606026 | F3: =IF('📇 INVENTARIO'!F4="","",'📇 INVENTARIO'!F4) -> G | G3: =IF('📇 INVENTARIO'!G4="","",'📇 INVENTARIO'!G4) -> 713 | H3: =IF('📇 INVENTARIO'!H4="","",'📇 INVENTARIO'!H4) -> 151 | I3: =IF('📇 INVENTARIO'!I4="","",'📇 INVENTARIO'!I4) -> 368.8 | J3: =IF('📇 INVENTARIO'!J4="","",'📇 INVENTARIO'!J4) -> 1958 | K3: =IF($C3="","",(G3-'⚙️ SUPUESTOS'!$C$20)/('⚙️ SUPUESTOS'!$C$25-'⚙️ SUPUESTOS'!$C$20)) -> 0.98106713 | L3: =IF($C3="","",VLOOKUP($E3,'📊 SECCIONES'!$B$4:$S$9,16,FALSE())) -> 1 | M3: =IF($C3="","",VLOOKUP($E3,'📊 SECCIONES'!$B$4:$S$9,17,FALSE())) -> 1 | N3: =IF($C3="","",VLOOKUP($E3,'📊 SECCIONES'!$B$4:$S$9,18,FALSE())) -> 0 | O3: =IF($C3="","",ROUND('⚙️ SUPUESTOS'!$C$21*K3+'⚙️ SUPUESTOS'!$C$22*L3+'⚙️ SUPUESTOS'!$C$23*M3+'⚙️ SUPUESTOS'!$C$24*N3,4)) -> 0.8996 | P3: =IF($C3="","",VLOOKUP($E3,'📊 SECCIONES'!$B$4:$S$9,7,FALSE())) -> 66.51 | Q3: =IF($C3="","",VLOOKUP($E3,'📊 SECCIONES'!$B$4:$S$9,8,FALSE())) -> 17450 | R3: =IF($C3="","",VLOOKUP($E3,'📊 SECCIONES'!$B$4:$S$9,10,FALSE())) -> 10.6 | S3: =IF('📇 INVENTARIO'!K4="","",'📇 INVENTARIO'!K4) -> 5 | T3: =IF($C3="","","Objetivo: alcanzar calificación C. Actual: Cal."&F3&". "&IF(OR(F3="G",F3="F"),"SATE integral + cubierta + carpinterías triple + aerotermia + instalación fotovoltaica",IF(F3="E","SATE fachada + carpinterías doble + instalación fotovoltaica",IF(F3="D","Mantenimiento de envolvente + instalación fotovoltaica en cubierta","Optimización energética + instalación fotovoltaica")))) -> Objetivo: alcanzar calificación C. Actual: Cal.G. SATE integral + cubierta + carpinterías triple + aerotermia + instalación fotovoltaica | U3: =IF($C3="","",IF(S3=0,"s/d",IF(S3>=4,"Valorar ascensor (verificar)","—"))) -> Valorar ascensor (verificar) | V3: =IF('📇 INVENTARIO'!L4="","",'📇 INVENTARIO'!L4) -> 330.5 | W3: =IF($C3="","",V3*'⚙️ SUPUESTOS'!$C$8*'⚙️ SUPUESTOS'!$C$9) -> 69.405 | X3: =IF('📇 INVENTARIO'!N4="","",'📇 INVENTARIO'!N4) -> 1373 | Y3: =IF($C3="","",W3*X3*'⚙️ SUPUESTOS'!$C$7) -> 85763.759 | Z3: =IF($C3="","",W3*'⚙️ SUPUESTOS'!$C$10) -> 92655.675 | AA3: =IF($C3="","",Y3*('⚙️ SUPUESTOS'!$C$12*'⚙️ SUPUESTOS'!$C$11+(1-'⚙️ SUPUESTOS'!$C$12)*'⚙️ SUPUESTOS'!$C$13)) -> 5849.0883 | AB3: =IF($C3="","",IF(Y3>0,ROUND(Y3*'⚙️ SUPUESTOS'!$C$12*'⚙️ SUPUESTOS'!$C$11,0),"")) -> 2144 | AC3: =IF($C3="","",IF(Y3>0,ROUND(Y3*(1-'⚙️ SUPUESTOS'!$C$12)*'⚙️ SUPUESTOS'!$C$13,0),"")) -> 3705 | AD3: =IF($C3="","",IF(AND(ISNUMBER(AA3),ISNUMBER(AE3),AA3>0,AE3>0),ROUND(AA3*MAX(0,25-AE3),0),"")) -> 53572 | AE3: =IF($C3="","",IF(AA3>0,Z3/AA3,"")) -> 15.841046 | AF3: =IF($C3="","",IF(AE3="","—",IF(AE3<='⚙️ SUPUESTOS'!$C$32,"✔ Muy recomendable",IF(AE3<='⚙️ SUPUESTOS'!$C$33,"✔ Recomendable","Valorar")))) -> ✔ Recomendable | AG3: =IF('📇 INVENTARIO'!O4="","",'📇 INVENTARIO'!O4) -> 41.649797 | AH3: =IF('📇 INVENTARIO'!P4="","",'📇 INVENTARIO'!P4) -> -4.710882
A4: =IF($C4="","",RANK(O4,$O$3:$O$265,0)+COUNTIF($O$3:O4,O4)-1) -> 2 | B4: =IF($C4="","",IF(A4<='⚙️ SUPUESTOS'!$C$29,"Fase 1",IF(A4<='⚙️ SUPUESTOS'!$C$30,"Fase 2","Fase 3"))) -> Fase 1 | C4: =IF('📇 INVENTARIO'!B5="","",'📇 INVENTARIO'!B5) -> C/ Pavo Real, 21 | D4: =IF('📇 INVENTARIO'!C5="","",'📇 INVENTARIO'!C5) -> 7625404UM5172F | E4: =IF('📇 INVENTARIO'!D5="","",'📇 INVENTARIO'!D5) -> 4718606026 | F4: =IF('📇 INVENTARIO'!F5="","",'📇 INVENTARIO'!F5) -> G | G4: =IF('📇 INVENTARIO'!G5="","",'📇 INVENTARIO'!G5) -> 630 | H4: =IF('📇 INVENTARIO'!H5="","",'📇 INVENTARIO'!H5) -> 107 | I4: =IF('📇 INVENTARIO'!I5="","",'📇 INVENTARIO'!I5) -> 178.9 | J4: =IF('📇 INVENTARIO'!J5="","",'📇 INVENTARIO'!J5) -> 1965 | K4: =IF($C4="","",(G4-'⚙️ SUPUESTOS'!$C$20)/('⚙️ SUPUESTOS'!$C$25-'⚙️ SUPUESTOS'!$C$20)) -> 0.83820998 | L4: =IF($C4="","",VLOOKUP($E4,'📊 SECCIONES'!$B$4:$S$9,16,FALSE())) -> 1 | M4: =IF($C4="","",VLOOKUP($E4,'📊 SECCIONES'!$B$4:$S$9,17,FALSE())) -> 1 | N4: =IF($C4="","",VLOOKUP($E4,'📊 SECCIONES'!$B$4:$S$9,18,FALSE())) -> 0 | O4: =IF($C4="","",ROUND('⚙️ SUPUESTOS'!$C$21*K4+'⚙️ SUPUESTOS'!$C$22*L4+'⚙️ SUPUESTOS'!$C$23*M4+'⚙️ SUPUESTOS'!$C$24*N4,4)) -> 0.821 | P4: =IF($C4="","",VLOOKUP($E4,'📊 SECCIONES'!$B$4:$S$9,7,FALSE())) -> 66.51 | Q4: =IF($C4="","",VLOOKUP($E4,'📊 SECCIONES'!$B$4:$S$9,8,FALSE())) -> 17450 | R4: =IF($C4="","",VLOOKUP($E4,'📊 SECCIONES'!$B$4:$S$9,10,FALSE())) -> 10.6 | S4: =IF('📇 INVENTARIO'!K5="","",'📇 INVENTARIO'!K5) -> 3 | T4: =IF($C4="","","Objetivo: alcanzar calificación C. Actual: Cal."&F4&". "&IF(OR(F4="G",F4="F"),"SATE integral + cubierta + carpinterías triple + aerotermia + instalación fotovoltaica",IF(F4="E","SATE fachada + carpinterías doble + instalación fotovoltaica",IF(F4="D","Mantenimiento de envolvente + instalación fotovoltaica en cubierta","Optimización energética + instalación fotovoltaica")))) -> Objetivo: alcanzar calificación C. Actual: Cal.G. SATE integral + cubierta + carpinterías triple + aerotermia + instalación fotovoltaica | U4: =IF($C4="","",IF(S4=0,"s/d",IF(S4>=4,"Valorar ascensor (verificar)","—"))) -> — | V4: =IF('📇 INVENTARIO'!L5="","",'📇 INVENTARIO'!L5) -> 96.2 | W4: =IF($C4="","",V4*'⚙️ SUPUESTOS'!$C$8*'⚙️ SUPUESTOS'!$C$9) -> 20.202 | X4: =IF('📇 INVENTARIO'!N5="","",'📇 INVENTARIO'!N5) -> 1477 | Y4: =IF($C4="","",W4*X4*'⚙️ SUPUESTOS'!$C$7) -> 26854.519 | Z4: =IF($C4="","",W4*'⚙️ SUPUESTOS'!$C$10) -> 26969.67 | AA4: =IF($C4="","",Y4*('⚙️ SUPUESTOS'!$C$12*'⚙️ SUPUESTOS'!$C$11+(1-'⚙️ SUPUESTOS'!$C$12)*'⚙️ SUPUESTOS'!$C$13)) -> 1831.4782 | AB4: =IF($C4="","",IF(Y4>0,ROUND(Y4*'⚙️ SUPUESTOS'!$C$12*'⚙️ SUPUESTOS'!$C$11,0),"")) -> 671 | AC4: =IF($C4="","",IF(Y4>0,ROUND(Y4*(1-'⚙️ SUPUESTOS'!$C$12)*'⚙️ SUPUESTOS'!$C$13,0),"")) -> 1160 | AD4: =IF($C4="","",IF(AND(ISNUMBER(AA4),ISNUMBER(AE4),AA4>0,AE4>0),ROUND(AA4*MAX(0,25-AE4),0),"")) -> 18817 | AE4: =IF($C4="","",IF(AA4>0,Z4/AA4,"")) -> 14.72563 | AF4: =IF($C4="","",IF(AE4="","—",IF(AE4<='⚙️ SUPUESTOS'!$C$32,"✔ Muy recomendable",IF(AE4<='⚙️ SUPUESTOS'!$C$33,"✔ Recomendable","Valorar")))) -> ✔ Muy recomendable | AG4: =IF('📇 INVENTARIO'!O5="","",'📇 INVENTARIO'!O5) -> 41.64943 | AH4: =IF('📇 INVENTARIO'!P5="","",'📇 INVENTARIO'!P5) -> -4.71056
A5: =IF($C5="","",RANK(O5,$O$3:$O$265,0)+COUNTIF($O$3:O5,O5)-1) -> 3 | B5: =IF($C5="","",IF(A5<='⚙️ SUPUESTOS'!$C$29,"Fase 1",IF(A5<='⚙️ SUPUESTOS'!$C$30,"Fase 2","Fase 3"))) -> Fase 1 | C5: =IF('📇 INVENTARIO'!B6="","",'📇 INVENTARIO'!B6) -> C/ Salud, 17 | D5: =IF('📇 INVENTARIO'!C6="","",'📇 INVENTARIO'!C6) -> 7625401UM5172F | E5: =IF('📇 INVENTARIO'!D6="","",'📇 INVENTARIO'!D6) -> 4718606026 | F5: =IF('📇 INVENTARIO'!F6="","",'📇 INVENTARIO'!F6) -> G | G5: =IF('📇 INVENTARIO'!G6="","",'📇 INVENTARIO'!G6) -> 528 | H5: =IF('📇 INVENTARIO'!H6="","",'📇 INVENTARIO'!H6) -> 90 | I5: =IF('📇 INVENTARIO'!I6="","",'📇 INVENTARIO'!I6) -> 211 | J5: =IF('📇 INVENTARIO'!J6="","",'📇 INVENTARIO'!J6) -> 1958 | K5: =IF($C5="","",(G5-'⚙️ SUPUESTOS'!$C$20)/('⚙️ SUPUESTOS'!$C$25-'⚙️ SUPUESTOS'!$C$20)) -> 0.6626506 | L5: =IF($C5="","",VLOOKUP($E5,'📊 SECCIONES'!$B$4:$S$9,16,FALSE())) -> 1 | M5: =IF($C5="","",VLOOKUP($E5,'📊 SECCIONES'!$B$4:$S$9,17,FALSE())) -> 1 | N5: =IF($C5="","",VLOOKUP($E5,'📊 SECCIONES'!$B$4:$S$9,18,FALSE())) -> 0 | O5: =IF($C5="","",ROUND('⚙️ SUPUESTOS'!$C$21*K5+'⚙️ SUPUESTOS'!$C$22*L5+'⚙️ SUPUESTOS'!$C$23*M5+'⚙️ SUPUESTOS'!$C$24*N5,4)) -> 0.7245 | P5: =IF($C5="","",VLOOKUP($E5,'📊 SECCIONES'!$B$4:$S$9,7,FALSE())) -> 66.51 | Q5: =IF($C5="","",VLOOKUP($E5,'📊 SECCIONES'!$B$4:$S$9,8,FALSE())) -> 17450 | R5: =IF($C5="","",VLOOKUP($E5,'📊 SECCIONES'!$B$4:$S$9,10,FALSE())) -> 10.6 | S5: =IF('📇 INVENTARIO'!K6="","",'📇 INVENTARIO'!K6) -> 5 | T5: =IF($C5="","","Objetivo: alcanzar calificación C. Actual: Cal."&F5&". "&IF(OR(F5="G",F5="F"),"SATE integral + cubierta + carpinterías triple + aerotermia + instalación fotovoltaica",IF(F5="E","SATE fachada + carpinterías doble + instalación fotovoltaica",IF(F5="D","Mantenimiento de envolvente + instalación fotovoltaica en cubierta","Optimización energética + instalación fotovoltaica")))) -> Objetivo: alcanzar calificación C. Actual: Cal.G. SATE integral + cubierta + carpinterías triple + aerotermia + instalación fotovoltaica | U5: =IF($C5="","",IF(S5=0,"s/d",IF(S5>=4,"Valorar ascensor (verificar)","—"))) -> Valorar ascensor (verificar) | V5: =IF('📇 INVENTARIO'!L6="","",'📇 INVENTARIO'!L6) -> 330.5 | W5: =IF($C5="","",V5*'⚙️ SUPUESTOS'!$C$8*'⚙️ SUPUESTOS'!$C$9) -> 69.405 | X5: =IF('📇 INVENTARIO'!N6="","",'📇 INVENTARIO'!N6) -> 1373 | Y5: =IF($C5="","",W5*X5*'⚙️ SUPUESTOS'!$C$7) -> 85763.759 | Z5: =IF($C5="","",W5*'⚙️ SUPUESTOS'!$C$10) -> 92655.675 | AA5: =IF($C5="","",Y5*('⚙️ SUPUESTOS'!$C$12*'⚙️ SUPUESTOS'!$C$11+(1-'⚙️ SUPUESTOS'!$C$12)*'⚙️ SUPUESTOS'!$C$13)) -> 5849.0883 | AB5: =IF($C5="","",IF(Y5>0,ROUND(Y5*'⚙️ SUPUESTOS'!$C$12*'⚙️ SUPUESTOS'!$C$11,0),"")) -> 2144 | AC5: =IF($C5="","",IF(Y5>0,ROUND(Y5*(1-'⚙️ SUPUESTOS'!$C$12)*'⚙️ SUPUESTOS'!$C$13,0),"")) -> 3705 | AD5: =IF($C5="","",IF(AND(ISNUMBER(AA5),ISNUMBER(AE5),AA5>0,AE5>0),ROUND(AA5*MAX(0,25-AE5),0),"")) -> 53572 | AE5: =IF($C5="","",IF(AA5>0,Z5/AA5,"")) -> 15.841046 | AF5: =IF($C5="","",IF(AE5="","—",IF(AE5<='⚙️ SUPUESTOS'!$C$32,"✔ Muy recomendable",IF(AE5<='⚙️ SUPUESTOS'!$C$33,"✔ Recomendable","Valorar")))) -> ✔ Recomendable | AG5: =IF('📇 INVENTARIO'!O6="","",'📇 INVENTARIO'!O6) -> 41.649497 | AH5: =IF('📇 INVENTARIO'!P6="","",'📇 INVENTARIO'!P6) -> -4.711089
A6: =IF($C6="","",RANK(O6,$O$3:$O$265,0)+COUNTIF($O$3:O6,O6)-1) -> 4 | B6: =IF($C6="","",IF(A6<='⚙️ SUPUESTOS'!$C$29,"Fase 1",IF(A6<='⚙️ SUPUESTOS'!$C$30,"Fase 2","Fase 3"))) -> Fase 1 | C6: =IF('📇 INVENTARIO'!B7="","",'📇 INVENTARIO'!B7) -> C/ Halcón, 2 | D6: =IF('📇 INVENTARIO'!C7="","",'📇 INVENTARIO'!C7) -> 7925705UM5172F | E6: =IF('📇 INVENTARIO'!D7="","",'📇 INVENTARIO'!D7) -> 4718606023 | F6: =IF('📇 INVENTARIO'!F7="","",'📇 INVENTARIO'!F7) -> G | G6: =IF('📇 INVENTARIO'!G7="","",'📇 INVENTARIO'!G7) -> 646 | H6: =IF('📇 INVENTARIO'!H7="","",'📇 INVENTARIO'!H7) -> 110 | I6: =IF('📇 INVENTARIO'!I7="","",'📇 INVENTARIO'!I7) -> 218.2 | J6: =IF('📇 INVENTARIO'!J7="","",'📇 INVENTARIO'!J7) -> 1965 | K6: =IF($C6="","",(G6-'⚙️ SUPUESTOS'!$C$20)/('⚙️ SUPUESTOS'!$C$25-'⚙️ SUPUESTOS'!$C$20)) -> 0.86574871 | L6: =IF($C6="","",VLOOKUP($E6,'📊 SECCIONES'!$B$4:$S$9,16,FALSE())) -> 0.54128061 | M6: =IF($C6="","",VLOOKUP($E6,'📊 SECCIONES'!$B$4:$S$9,17,FALSE())) -> 0.59585492 | N6: =IF($C6="","",VLOOKUP($E6,'📊 SECCIONES'!$B$4:$S$9,18,FALSE())) -> 0.28636364 | O6: =IF($C6="","",ROUND('⚙️ SUPUESTOS'!$C$21*K6+'⚙️ SUPUESTOS'!$C$22*L6+'⚙️ SUPUESTOS'!$C$23*M6+'⚙️ SUPUESTOS'!$C$24*N6,4)) -> 0.7044 | P6: =IF($C6="","",VLOOKUP($E6,'📊 SECCIONES'!$B$4:$S$9,7,FALSE())) -> 39.41 | Q6: =IF($C6="","",VLOOKUP($E6,'📊 SECCIONES'!$B$4:$S$9,8,FALSE())) -> 22486 | R6: =IF($C6="","",VLOOKUP($E6,'📊 SECCIONES'!$B$4:$S$9,10,FALSE())) -> 16.9 | S6: =IF('📇 INVENTARIO'!K7="","",'📇 INVENTARIO'!K7) -> 3 | T6: =IF($C6="","","Objetivo: alcanzar calificación C. Actual: Cal."&F6&". "&IF(OR(F6="G",F6="F"),"SATE integral + cubierta + carpinterías triple + aerotermia + instalación fotovoltaica",IF(F6="E","SATE fachada + carpinterías doble + instalación fotovoltaica",IF(F6="D","Mantenimiento de envolvente + instalación fotovoltaica en cubierta","Optimización energética + instalación fotovoltaica")))) -> Objetivo: alcanzar calificación C. Actual: Cal.G. SATE integral + cubierta + carpinterías triple + aerotermia + instalación fotovoltaica | U6: =IF($C6="","",IF(S6=0,"s/d",IF(S6>=4,"Valorar ascensor (verificar)","—"))) -> — | V6: =IF('📇 INVENTARIO'!L7="","",'📇 INVENTARIO'!L7) -> 102.1 | W6: =IF($C6="","",V6*'⚙️ SUPUESTOS'!$C$8*'⚙️ SUPUESTOS'!$C$9) -> 21.441 | X6: =IF('📇 INVENTARIO'!N7="","",'📇 INVENTARIO'!N7) -> 1380 | Y6: =IF($C6="","",W6*X6*'⚙️ SUPUESTOS'!$C$7) -> 26629.722 | Z6: =IF($C6="","",W6*'⚙️ SUPUESTOS'!$C$10) -> 28623.735 | AA6: =IF($C6="","",Y6*('⚙️ SUPUESTOS'!$C$12*'⚙️ SUPUESTOS'!$C$11+(1-'⚙️ SUPUESTOS'!$C$12)*'⚙️ SUPUESTOS'!$C$13)) -> 1816.147 | AB6: =IF($C6="","",IF(Y6>0,ROUND(Y6*'⚙️ SUPUESTOS'!$C$12*'⚙️ SUPUESTOS'!$C$11,0),"")) -> 666 | AC6: =IF($C6="","",IF(Y6>0,ROUND(Y6*(1-'⚙️ SUPUESTOS'!$C$12)*'⚙️ SUPUESTOS'!$C$13,0),"")) -> 1150 | AD6: =IF($C6="","",IF(AND(ISNUMBER(AA6),ISNUMBER(AE6),AA6>0,AE6>0),ROUND(AA6*MAX(0,25-AE6),0),"")) -> 16780 | AE6: =IF($C6="","",IF(AA6>0,Z6/AA6,"")) -> 15.760692 | AF6: =IF($C6="","",IF(AE6="","—",IF(AE6<='⚙️ SUPUESTOS'!$C$32,"✔ Muy recomendable",IF(AE6<='⚙️ SUPUESTOS'!$C$33,"✔ Recomendable","Valorar")))) -> ✔ Recomendable | AG6: =IF('📇 INVENTARIO'!O7="","",'📇 INVENTARIO'!O7) -> 41.64986 | AH6: =IF('📇 INVENTARIO'!P7="","",'📇 INVENTARIO'!P7) -> -4.70842
A7: =IF($C7="","",RANK(O7,$O$3:$O$265,0)+COUNTIF($O$3:O7,O7)-1) -> 5 | B7: =IF($C7="","",IF(A7<='⚙️ SUPUESTOS'!$C$29,"Fase 1",IF(A7<='⚙️ SUPUESTOS'!$C$30,"Fase 2","Fase 3"))) -> Fase 1 | C7: =IF('📇 INVENTARIO'!B8="","",'📇 INVENTARIO'!B8) -> C/ Rincón del Esgueva, 13 | D7: =IF('📇 INVENTARIO'!C8="","",'📇 INVENTARIO'!C8) -> 7726409UM5172F | E7: =IF('📇 INVENTARIO'!D8="","",'📇 INVENTARIO'!D8) -> 4718606023 | F7: =IF('📇 INVENTARIO'!F8="","",'📇 INVENTARIO'!F8) -> G | G7: =IF('📇 INVENTARIO'!G8="","",'📇 INVENTARIO'!G8) -> 634 | H7: =IF('📇 INVENTARIO'!H8="","",'📇 INVENTARIO'!H8) -> 134 | I7: =IF('📇 INVENTARIO'!I8="","",'📇 INVENTARIO'!I8) -> 334.2 | J7: =IF('📇 INVENTARIO'!J8="","",'📇 INVENTARIO'!J8) -> 1936 | K7: =IF($C7="","",(G7-'⚙️ SUPUESTOS'!$C$20)/('⚙️ SUPUESTOS'!$C$25-'⚙️ SUPUESTOS'!$C$20)) -> 0.84509466 | L7: =IF($C7="","",VLOOKUP($E7,'📊 SECCIONES'!$B$4:$S$9,16,FALSE())) -> 0.54128061 | M7: =IF($C7="","",VLOOKUP($E7,'📊 SECCIONES'!$B$4:$S$9,17,FALSE())) -> 0.59585492 | N7: =IF($C7="","",VLOOKUP($E7,'📊 SECCIONES'!$B$4:$S$9,18,FALSE())) -> 0.28636364 | O7: =IF($C7="","",ROUND('⚙️ SUPUESTOS'!$C$21*K7+'⚙️ SUPUESTOS'!$C$22*L7+'⚙️ SUPUESTOS'!$C$23*M7+'⚙️ SUPUESTOS'!$C$24*N7,4)) -> 0.6931 | P7: =IF($C7="","",VLOOKUP($E7,'📊 SECCIONES'!$B$4:$S$9,7,FALSE())) -> 39.41 | Q7: =IF($C7="","",VLOOKUP($E7,'📊 SECCIONES'!$B$4:$S$9,8,FALSE())) -> 22486 | R7: =IF($C7="","",VLOOKUP($E7,'📊 SECCIONES'!$B$4:$S$9,10,FALSE())) -> 16.9 | S7: =IF('📇 INVENTARIO'!K8="","",'📇 INVENTARIO'!K8) -> 1 | T7: =IF($C7="","","Objetivo: alcanzar calificación C. Actual: Cal."&F7&". "&IF(OR(F7="G",F7="F"),"SATE integral + cubierta + carpinterías triple + aerotermia + instalación fotovoltaica",IF(F7="E","SATE fachada + carpinterías doble + instalación fotovoltaica",IF(F7="D","Mantenimiento de envolvente + instalación fotovoltaica en cubierta","Optimización energética + instalación fotovoltaica")))) -> Objetivo: alcanzar calificación C. Actual: Cal.G. SATE integral + cubierta + carpinterías triple + aerotermia + instalación fotovoltaica | U7: =IF($C7="","",IF(S7=0,"s/d",IF(S7>=4,"Valorar ascensor (verificar)","—"))) -> — | V7: =IF('📇 INVENTARIO'!L8="","",'📇 INVENTARIO'!L8) -> 53.6 | W7: =IF($C7="","",V7*'⚙️ SUPUESTOS'!$C$8*'⚙️ SUPUESTOS'!$C$9) -> 11.256 | X7: =IF('📇 INVENTARIO'!N8="","",'📇 INVENTARIO'!N8) -> 1515 | Y7: =IF($C7="","",W7*X7*'⚙️ SUPUESTOS'!$C$7) -> 15347.556 | Z7: =IF($C7="","",W7*'⚙️ SUPUESTOS'!$C$10) -> 15026.76 | AA7: =IF($C7="","",Y7*('⚙️ SUPUESTOS'!$C$12*'⚙️ SUPUESTOS'!$C$11+(1-'⚙️ SUPUESTOS'!$C$12)*'⚙️ SUPUESTOS'!$C$13)) -> 1046.7033 | AB7: =IF($C7="","",IF(Y7>0,ROUND(Y7*'⚙️ SUPUESTOS'!$C$12*'⚙️ SUPUESTOS'!$C$11,0),"")) -> 384 | AC7: =IF($C7="","",IF(Y7>0,ROUND(Y7*(1-'⚙️ SUPUESTOS'!$C$12)*'⚙️ SUPUESTOS'!$C$13,0),"")) -> 663 | AD7: =IF($C7="","",IF(AND(ISNUMBER(AA7),ISNUMBER(AE7),AA7>0,AE7>0),ROUND(AA7*MAX(0,25-AE7),0),"")) -> 11141 | AE7: =IF($C7="","",IF(AA7>0,Z7/AA7,"")) -> 14.356274 | AF7: =IF($C7="","",IF(AE7="","—",IF(AE7<='⚙️ SUPUESTOS'!$C$32,"✔ Muy recomendable",IF(AE7<='⚙️ SUPUESTOS'!$C$33,"✔ Recomendable","Valorar")))) -> ✔ Muy recomendable | AG7: =IF('📇 INVENTARIO'!O8="","",'📇 INVENTARIO'!O8) -> 41.65012 | AH7: =IF('📇 INVENTARIO'!P8="","",'📇 INVENTARIO'!P8) -> -4.70963
A8: =IF($C8="","",RANK(O8,$O$3:$O$265,0)+COUNTIF($O$3:O8,O8)-1) -> 6 | B8: =IF($C8="","",IF(A8<='⚙️ SUPUESTOS'!$C$29,"Fase 1",IF(A8<='⚙️ SUPUESTOS'!$C$30,"Fase 2","Fase 3"))) -> Fase 1 | C8: =IF('📇 INVENTARIO'!B9="","",'📇 INVENTARIO'!B9) -> C/ Calandria, 4 | D8: =IF('📇 INVENTARIO'!C9="","",'📇 INVENTARIO'!C9) -> 7925710UM5172F | E8: =IF('📇 INVENTARIO'!D9="","",'📇 INVENTARIO'!D9) -> 4718606023 | F8: =IF('📇 INVENTARIO'!F9="","",'📇 INVENTARIO'!F9) -> G | G8: =IF('📇 INVENTARIO'!G9="","",'📇 INVENTARIO'!G9) -> 632 | H8: =IF('📇 INVENTARIO'!H9="","",'📇 INVENTARIO'!H9) -> 134 | I8: =IF('📇 INVENTARIO'!I9="","",'📇 INVENTARIO'!I9) -> 251.9 | J8: =IF('📇 INVENTARIO'!J9="","",'📇 INVENTARIO'!J9) -> 1965 | K8: =IF($C8="","",(G8-'⚙️ SUPUESTOS'!$C$20)/('⚙️ SUPUESTOS'!$C$25-'⚙️ SUPUESTOS'!$C$20)) -> 0.84165232 | L8: =IF($C8="","",VLOOKUP($E8,'📊 SECCIONES'!$B$4:$S$9,16,FALSE())) -> 0.54128061 | M8: =IF($C8="","",VLOOKUP($E8,'📊 SECCIONES'!$B$4:$S$9,17,FALSE())) -> 0.59585492 | N8: =IF($C8="","",VLOOKUP($E8,'📊 SECCIONES'!$B$4:$S$9,18,FALSE())) -> 0.28636364 | O8: =IF($C8="","",ROUND('⚙️ SUPUESTOS'!$C$21*K8+'⚙️ SUPUESTOS'!$C$22*L8+'⚙️ SUPUESTOS'!$C$23*M8+'⚙️ SUPUESTOS'!$C$24*N8,4)) -> 0.6912 | P8: =IF($C8="","",VLOOKUP($E8,'📊 SECCIONES'!$B$4:$S$9,7,FALSE())) -> 39.41 | Q8: =IF($C8="","",VLOOKUP($E8,'📊 SECCIONES'!$B$4:$S$9,8,FALSE())) -> 22486 | R8: =IF($C8="","",VLOOKUP($E8,'📊 SECCIONES'!$B$4:$S$9,10,FALSE())) -> 16.9 | S8: =IF('📇 INVENTARIO'!K9="","",'📇 INVENTARIO'!K9) -> 3 | T8: =IF($C8="","","Objetivo: alcanzar calificación C. Actual: Cal."&F8&". "&IF(OR(F8="G",F8="F"),"SATE integral + cubierta + carpinterías triple + aerotermia + instalación fotovoltaica",IF(F8="E","SATE fachada + carpinterías doble + instalación fotovoltaica",IF(F8="D","Mantenimiento de envolvente + instalación fotovoltaica en cubierta","Optimización energética + instalación fotovoltaica")))) -> Objetivo: alcanzar calificación C. Actual: Cal.G. SATE integral + cubierta + carpinterías triple + aerotermia + instalación fotovoltaica | U8: =IF($C8="","",IF(S8=0,"s/d",IF(S8>=4,"Valorar ascensor (verificar)","—"))) -> — | V8: =IF('📇 INVENTARIO'!L9="","",'📇 INVENTARIO'!L9) -> 101.6 | W8: =IF($C8="","",V8*'⚙️ SUPUESTOS'!$C$8*'⚙️ SUPUESTOS'!$C$9) -> 21.336 | X8: =IF('📇 INVENTARIO'!N9="","",'📇 INVENTARIO'!N9) -> 1366 | Y8: =IF($C8="","",W8*X8*'⚙️ SUPUESTOS'!$C$7) -> 26230.478 | Z8: =IF($C8="","",W8*'⚙️ SUPUESTOS'!$C$10) -> 28483.56 | AA8: =IF($C8="","",Y8*('⚙️ SUPUESTOS'!$C$12*'⚙️ SUPUESTOS'!$C$11+(1-'⚙️ SUPUESTOS'!$C$12)*'⚙️ SUPUESTOS'!$C$13)) -> 1788.9186 | AB8: =IF($C8="","",IF(Y8>0,ROUND(Y8*'⚙️ SUPUESTOS'!$C$12*'⚙️ SUPUESTOS'!$C$11,0),"")) -> 656 | AC8: =IF($C8="","",IF(Y8>0,ROUND(Y8*(1-'⚙️ SUPUESTOS'!$C$12)*'⚙️ SUPUESTOS'!$C$13,0),"")) -> 1133 | AD8: =IF($C8="","",IF(AND(ISNUMBER(AA8),ISNUMBER(AE8),AA8>0,AE8>0),ROUND(AA8*MAX(0,25-AE8),0),"")) -> 16239 | AE8: =IF($C8="","",IF(AA8>0,Z8/AA8,"")) -> 15.922222 | AF8: =IF($C8="","",IF(AE8="","—",IF(AE8<='⚙️ SUPUESTOS'!$C$32,"✔ Muy recomendable",IF(AE8<='⚙️ SUPUESTOS'!$C$33,"✔ Recomendable","Valorar")))) -> ✔ Recomendable | AG8: =IF('📇 INVENTARIO'!O9="","",'📇 INVENTARIO'!O9) -> 41.64975 | AH8: =IF('📇 INVENTARIO'!P9="","",'📇 INVENTARIO'!P9) -> -4.70784
A9: =IF($C9="","",RANK(O9,$O$3:$O$265,0)+COUNTIF($O$3:O9,O9)-1) -> 7 | B9: =IF($C9="","",IF(A9<='⚙️ SUPUESTOS'!$C$29,"Fase 1",IF(A9<='⚙️ SUPUESTOS'!$C$30,"Fase 2","Fase 3"))) -> Fase 1 | C9: =IF('📇 INVENTARIO'!B11="","",'📇 INVENTARIO'!B11) -> C/ Marabú, 1 | D9: =IF('📇 INVENTARIO'!C11="","",'📇 INVENTARIO'!C11) -> 7924213UM5172D | E9: =IF('📇 INVENTARIO'!D11="","",'📇 INVENTARIO'!D11) -> 4718606024 | F9: =IF('📇 INVENTARIO'!F11="","",'📇 INVENTARIO'!F11) -> G | G9: =IF('📇 INVENTARIO'!G11="","",'📇 INVENTARIO'!G11) -> 724 | H9: =IF('📇 INVENTARIO'!H11="","",'📇 INVENTARIO'!H11) -> 148 | I9: =IF('📇 INVENTARIO'!I11="","",'📇 INVENTARIO'!I11) -> 374.5 | J9: =IF('📇 INVENTARIO'!J11="","",'📇 INVENTARIO'!J11) -> 1965 | K9: =IF($C9="","",(G9-'⚙️ SUPUESTOS'!$C$20)/('⚙️ SUPUESTOS'!$C$25-'⚙️ SUPUESTOS'!$C$20)) -> 1 | L9: =IF($C9="","",VLOOKUP($E9,'📊 SECCIONES'!$B$4:$S$9,16,FALSE())) -> 0.13391193 | M9: =IF($C9="","",VLOOKUP($E9,'📊 SECCIONES'!$B$4:$S$9,17,FALSE())) -> 0.16476684 | N9: =IF($C9="","",VLOOKUP($E9,'📊 SECCIONES'!$B$4:$S$9,18,FALSE())) -> 0.79545455 | O9: =IF($C9="","",ROUND('⚙️ SUPUESTOS'!$C$21*K9+'⚙️ SUPUESTOS'!$C$22*L9+'⚙️ SUPUESTOS'!$C$23*M9+'⚙️ SUPUESTOS'!$C$24*N9,4)) -> 0.6741 | P9: =IF($C9="","",VLOOKUP($E9,'📊 SECCIONES'!$B$4:$S$9,7,FALSE())) -> 30.06 | Q9: =IF($C9="","",VLOOKUP($E9,'📊 SECCIONES'!$B$4:$S$9,8,FALSE())) -> 25132 | R9: =IF($C9="","",VLOOKUP($E9,'📊 SECCIONES'!$B$4:$S$9,10,FALSE())) -> 28.1 | S9: =IF('📇 INVENTARIO'!K11="","",'📇 INVENTARIO'!K11) -> 3 | T9: =IF($C9="","","Objetivo: alcanzar calificación C. Actual: Cal."&F9&". "&IF(OR(F9="G",F9="F"),"SATE integral + cubierta + carpinterías triple + aerotermia + instalación fotovoltaica",IF(F9="E","SATE fachada + carpinterías doble + instalación fotovoltaica",IF(F9="D","Mantenimiento de envolvente + instalación fotovoltaica en cubierta","Optimización energética + instalación fotovoltaica")))) -> Objetivo: alcanzar calificación C. Actual: Cal.G. SATE integral + cubierta + carpinterías triple + aerotermia + instalación fotovoltaica | U9: =IF($C9="","",IF(S9=0,"s/d",IF(S9>=4,"Valorar ascensor (verificar)","—"))) -> — | V9: =IF('📇 INVENTARIO'!L11="","",'📇 INVENTARIO'!L11) -> 97.4 | W9: =IF($C9="","",V9*'⚙️ SUPUESTOS'!$C$8*'⚙️ SUPUESTOS'!$C$9) -> 20.454 | X9: =IF('📇 INVENTARIO'!N11="","",'📇 INVENTARIO'!N11) -> 1394 | Y9: =IF($C9="","",W9*X9*'⚙️ SUPUESTOS'!$C$7) -> 25661.588 | Z9: =IF($C9="","",W9*'⚙️ SUPUESTOS'!$C$10) -> 27306.09 | AA9: =IF($C9="","",Y9*('⚙️ SUPUESTOS'!$C$12*'⚙️ SUPUESTOS'!$C$11+(1-'⚙️ SUPUESTOS'!$C$12)*'⚙️ SUPUESTOS'!$C$13)) -> 1750.1203 | AB9: =IF($C9="","",IF(Y9>0,ROUND(Y9*'⚙️ SUPUESTOS'!$C$12*'⚙️ SUPUESTOS'!$C$11,0),"")) -> 642 | AC9: =IF($C9="","",IF(Y9>0,ROUND(Y9*(1-'⚙️ SUPUESTOS'!$C$12)*'⚙️ SUPUESTOS'!$C$13,0),"")) -> 1109 | AD9: =IF($C9="","",IF(AND(ISNUMBER(AA9),ISNUMBER(AE9),AA9>0,AE9>0),ROUND(AA9*MAX(0,25-AE9),0),"")) -> 16447 | AE9: =IF($C9="","",IF(AA9>0,Z9/AA9,"")) -> 15.602407 | AF9: =IF($C9="","",IF(AE9="","—",IF(AE9<='⚙️ SUPUESTOS'!$C$32,"✔ Muy recomendable",IF(AE9<='⚙️ SUPUESTOS'!$C$33,"✔ Recomendable","Valorar")))) -> ✔ Recomendable | AG9: =IF('📇 INVENTARIO'!O10="","",'📇 INVENTARIO'!O10) -> 41.64922 | AH9: =IF('📇 INVENTARIO'!P10="","",'📇 INVENTARIO'!P10) -> -4.71073
A10: =IF($C10="","",RANK(O10,$O$3:$O$265,0)+COUNTIF($O$3:O10,O10)-1) -> 8 | B10: =IF($C10="","",IF(A10<='⚙️ SUPUESTOS'!$C$29,"Fase 1",IF(A10<='⚙️ SUPUESTOS'!$C$30,"Fase 2","Fase 3"))) -> Fase 1 | C10: =IF('📇 INVENTARIO'!B10="","",'📇 INVENTARIO'!B10) -> C/ Pavo Real, 17 | D10: =IF('📇 INVENTARIO'!C10="","",'📇 INVENTARIO'!C10) -> 7625406UM5172F | E10: =IF('📇 INVENTARIO'!D10="","",'📇 INVENTARIO'!D10) -> 4718606026 | F10: =IF('📇 INVENTARIO'!F10="","",'📇 INVENTARIO'!F10) -> G | G10: =IF('📇 INVENTARIO'!G10="","",'📇 INVENTARIO'!G10) -> 464 | H10: =IF('📇 INVENTARIO'!H10="","",'📇 INVENTARIO'!H10) -> 118 | I10: =IF('📇 INVENTARIO'!I10="","",'📇 INVENTARIO'!I10) -> 180.2 | J10: =IF('📇 INVENTARIO'!J10="","",'📇 INVENTARIO'!J10) -> 1965 | K10: =IF($C10="","",(G10-'⚙️ SUPUESTOS'!$C$20)/('⚙️ SUPUESTOS'!$C$25-'⚙️ SUPUESTOS'!$C$20)) -> 0.5524957 | L10: =IF($C10="","",VLOOKUP($E10,'📊 SECCIONES'!$B$4:$S$9,16,FALSE())) -> 1 | M10: =IF($C10="","",VLOOKUP($E10,'📊 SECCIONES'!$B$4:$S$9,17,FALSE())) -> 1 | N10: =IF($C10="","",VLOOKUP($E10,'📊 SECCIONES'!$B$4:$S$9,18,FALSE())) -> 0 | O10: =IF($C10="","",ROUND('⚙️ SUPUESTOS'!$C$21*K10+'⚙️ SUPUESTOS'!$C$22*L10+'⚙️ SUPUESTOS'!$C$23*M10+'⚙️ SUPUESTOS'!$C$24*N10,4)) -> 0.6639 | P10: =IF($C10="","",VLOOKUP($E10,'📊 SECCIONES'!$B$4:$S$9,7,FALSE())) -> 66.51 | Q10: =IF($C10="","",VLOOKUP($E10,'📊 SECCIONES'!$B$4:$S$9,8,FALSE())) -> 17450 | R10: =IF($C10="","",VLOOKUP($E10,'📊 SECCIONES'!$B$4:$S$9,10,FALSE())) -> 10.6 | S10: =IF('📇 INVENTARIO'!K10="","",'📇 INVENTARIO'!K10) -> 3 | T10: =IF($C10="","","Objetivo: alcanzar calificación C. Actual: Cal."&F10&". "&IF(OR(F10="G",F10="F"),"SATE integral + cubierta + carpinterías triple + aerotermia + instalación fotovoltaica",IF(F10="E","SATE fachada + carpinterías doble + instalación fotovoltaica",IF(F10="D","Mantenimiento de envolvente + instalación fotovoltaica en cubierta","Optimización energética + instalación fotovoltaica")))) -> Objetivo: alcanzar calificación C. Actual: Cal.G. SATE integral + cubierta + carpinterías triple + aerotermia + instalación fotovoltaica | U10: =IF($C10="","",IF(S10=0,"s/d",IF(S10>=4,"Valorar ascensor (verificar)","—"))) -> — | V10: =IF('📇 INVENTARIO'!L10="","",'📇 INVENTARIO'!L10) -> 95.1 | W10: =IF($C10="","",V10*'⚙️ SUPUESTOS'!$C$8*'⚙️ SUPUESTOS'!$C$9) -> 19.971 | X10: =IF('📇 INVENTARIO'!N10="","",'📇 INVENTARIO'!N10) -> 1467 | Y10: =IF($C10="","",W10*X10*'⚙️ SUPUESTOS'!$C$7) -> 26367.711 | Z10: =IF($C10="","",W10*'⚙️ SUPUESTOS'!$C$10) -> 26661.285 | AA10: =IF($C10="","",Y10*('⚙️ SUPUESTOS'!$C$12*'⚙️ SUPUESTOS'!$C$11+(1-'⚙️ SUPUESTOS'!$C$12)*'⚙️ SUPUESTOS'!$C$13)) -> 1798.2779 | AB10: =IF($C10="","",IF(Y10>0,ROUND(Y10*'⚙️ SUPUESTOS'!$C$12*'⚙️ SUPUESTOS'!$C$11,0),"")) -> 659 | AC10: =IF($C10="","",IF(Y10>0,ROUND(Y10*(1-'⚙️ SUPUESTOS'!$C$12)*'⚙️ SUPUESTOS'!$C$13,0),"")) -> 1139 | AD10: =IF($C10="","",IF(AND(ISNUMBER(AA10),ISNUMBER(AE10),AA10>0,AE10>0),ROUND(AA10*MAX(0,25-AE10),0),"")) -> 18296 | AE10: =IF($C10="","",IF(AA10>0,Z10/AA10,"")) -> 14.826009 | AF10: =IF($C10="","",IF(AE10="","—",IF(AE10<='⚙️ SUPUESTOS'!$C$32,"✔ Muy recomendable",IF(AE10<='⚙️ SUPUESTOS'!$C$33,"✔ Recomendable","Valorar")))) -> ✔ Muy recomendable | AG10: =IF('📇 INVENTARIO'!O11="","",'📇 INVENTARIO'!O11) -> 41.64934 | AH10: =IF('📇 INVENTARIO'!P11="","",'📇 INVENTARIO'!P11) -> -4.70757
A11: =IF($C11="","",RANK(O11,$O$3:$O$265,0)+COUNTIF($O$3:O11,O11)-1) -> 9 | B11: =IF($C11="","",IF(A11<='⚙️ SUPUESTOS'!$C$29,"Fase 1",IF(A11<='⚙️ SUPUESTOS'!$C$30,"Fase 2","Fase 3"))) -> Fase 1 | C11: =IF('📇 INVENTARIO'!B12="","",'📇 INVENTARIO'!B12) -> C/ Águila, 20 | D11: =IF('📇 INVENTARIO'!C12="","",'📇 INVENTARIO'!C12) -> 7824519UM5172D | E11: =IF('📇 INVENTARIO'!D12="","",'📇 INVENTARIO'!D12) -> 4718606026 | F11: =IF('📇 INVENTARIO'!F12="","",'📇 INVENTARIO'!F12) -> G | G11: =IF('📇 INVENTARIO'!G12="","",'📇 INVENTARIO'!G12) -> 461 | H11: =IF('📇 INVENTARIO'!H12="","",'📇 INVENTARIO'!H12) -> 79 | I11: =IF('📇 INVENTARIO'!I12="","",'📇 INVENTARIO'!I12) -> 155.4 | J11: =IF('📇 INVENTARIO'!J12="","",'📇 INVENTARIO'!J12) -> 1965 | K11: =IF($C11="","",(G11-'⚙️ SUPUESTOS'!$C$20)/('⚙️ SUPUESTOS'!$C$25-'⚙️ SUPUESTOS'!$C$20)) -> 0.54733219 | L11: =IF($C11="","",VLOOKUP($E11,'📊 SECCIONES'!$B$4:$S$9,16,FALSE())) -> 1 | M11: =IF($C11="","",VLOOKUP($E11,'📊 SECCIONES'!$B$4:$S$9,17,FALSE())) -> 1 | N11: =IF($C11="","",VLOOKUP($E11,'📊 SECCIONES'!$B$4:$S$9,18,FALSE())) -> 0 | O11: =IF($C11="","",ROUND('⚙️ SUPUESTOS'!$C$21*K11+'⚙️ SUPUESTOS'!$C$22*L11+'⚙️ SUPUESTOS'!$C$23*M11+'⚙️ SUPUESTOS'!$C$24*N11,4)) -> 0.661 | P11: =IF($C11="","",VLOOKUP($E11,'📊 SECCIONES'!$B$4:$S$9,7,FALSE())) -> 66.51 | Q11: =IF($C11="","",VLOOKUP($E11,'📊 SECCIONES'!$B$4:$S$9,8,FALSE())) -> 17450 | R11: =IF($C11="","",VLOOKUP($E11,'📊 SECCIONES'!$B$4:$S$9,10,FALSE())) -> 10.6 | S11: =IF('📇 INVENTARIO'!K12="","",'📇 INVENTARIO'!K12) -> 3 | T11: =IF($C11="","","Objetivo: alcanzar calificación C. Actual: Cal."&F11&". "&IF(OR(F11="G",F11="F"),"SATE integral + cubierta + carpinterías triple + aerotermia + instalación fotovoltaica",IF(F11="E","SATE fachada + carpinterías doble + instalación fotovoltaica",IF(F11="D","Mantenimiento de envolvente + instalación fotovoltaica en cubierta","Optimización energética + instalación fotovoltaica")))) -> Objetivo: alcanzar calificación C. Actual: Cal.G. SATE integral + cubierta + carpinterías triple + aerotermia + instalación fotovoltaica | U11: =IF($C11="","",IF(S11=0,"s/d",IF(S11>=4,"Valorar ascensor (verificar)","—"))) -> — | V11: =IF('📇 INVENTARIO'!L12="","",'📇 INVENTARIO'!L12) -> 110.7 | W11: =IF($C11="","",V11*'⚙️ SUPUESTOS'!$C$8*'⚙️ SUPUESTOS'!$C$9) -> 23.247 | X11: =IF('📇 INVENTARIO'!N12="","",'📇 INVENTARIO'!N12) -> 1517 | Y11: =IF($C11="","",W11*X11*'⚙️ SUPUESTOS'!$C$7) -> 31739.129 | Z11: =IF($C11="","",W11*'⚙️ SUPUESTOS'!$C$10) -> 31034.745 | AA11: =IF($C11="","",Y11*('⚙️ SUPUESTOS'!$C$12*'⚙️ SUPUESTOS'!$C$11+(1-'⚙️ SUPUESTOS'!$C$12)*'⚙️ SUPUESTOS'!$C$13)) -> 2164.6086 | AB11: =IF($C11="","",IF(Y11>0,ROUND(Y11*'⚙️ SUPUESTOS'!$C$12*'⚙️ SUPUESTOS'!$C$11,0),"")) -> 793 | AC11: =IF($C11="","",IF(Y11>0,ROUND(Y11*(1-'⚙️ SUPUESTOS'!$C$12)*'⚙️ SUPUESTOS'!$C$13,0),"")) -> 1371 | AD11: =IF($C11="","",IF(AND(ISNUMBER(AA11),ISNUMBER(AE11),AA11>0,AE11>0),ROUND(AA11*MAX(0,25-AE11),0),"")) -> 23080 | AE11: =IF($C11="","",IF(AA11>0,Z11/AA11,"")) -> 14.337347 | AF11: =IF($C11="","",IF(AE11="","—",IF(AE11<='⚙️ SUPUESTOS'!$C$32,"✔ Muy recomendable",IF(AE11<='⚙️ SUPUESTOS'!$C$33,"✔ Recomendable","Valorar")))) -> ✔ Muy recomendable | AG11: =IF('📇 INVENTARIO'!O12="","",'📇 INVENTARIO'!O12) -> 41.64889 | AH11: =IF('📇 INVENTARIO'!P12="","",'📇 INVENTARIO'!P12) -> -4.70906
A12: =IF($C12="","",RANK(O12,$O$3:$O$265,0)+COUNTIF($O$3:O12,O12)-1) -> 10 | B12: =IF($C12="","",IF(A12<='⚙️ SUPUESTOS'!$C$29,"Fase 1",IF(A12<='⚙️ SUPUESTOS'!$C$30,"Fase 2","Fase 3"))) -> Fase 1 | C12: =IF('📇 INVENTARIO'!B13="","",'📇 INVENTARIO'!B13) -> C/ Albatros, 1 | D12: =IF('📇 INVENTARIO'!C13="","",'📇 INVENTARIO'!C13) -> 7724226UM5172D | E12: =IF('📇 INVENTARIO'!D13="","",'📇 INVENTARIO'!D13) -> 4718606026 | F12: =IF('📇 INVENTARIO'!F13="","",'📇 INVENTARIO'!F13) -> G | G12: =IF('📇 INVENTARIO'!G13="","",'📇 INVENTARIO'!G13) -> 454 | H12: =IF('📇 INVENTARIO'!H13="","",'📇 INVENTARIO'!H13) -> 96 | I12: =IF('📇 INVENTARIO'!I13="","",'📇 INVENTARIO'!I13) -> 173.2 | J12: =IF('📇 INVENTARIO'!J13="","",'📇 INVENTARIO'!J13) -> 1965 | K12: =IF($C12="","",(G12-'⚙️ SUPUESTOS'!$C$20)/('⚙️ SUPUESTOS'!$C$25-'⚙️ SUPUESTOS'!$C$20)) -> 0.53528399 | L12: =IF($C12="","",VLOOKUP($E12,'📊 SECCIONES'!$B$4:$S$9,16,FALSE())) -> 1 | M12: =IF($C12="","",VLOOKUP($E12,'📊 SECCIONES'!$B$4:$S$9,17,FALSE())) -> 1 | N12: =IF($C12="","",VLOOKUP($E12,'📊 SECCIONES'!$B$4:$S$9,18,FALSE())) -> 0 | O12: =IF($C12="","",ROUND('⚙️ SUPUESTOS'!$C$21*K12+'⚙️ SUPUESTOS'!$C$22*L12+'⚙️ SUPUESTOS'!$C$23*M12+'⚙️ SUPUESTOS'!$C$24*N12,4)) -> 0.6544 | P12: =IF($C12="","",VLOOKUP($E12,'📊 SECCIONES'!$B$4:$S$9,7,FALSE())) -> 66.51 | Q12: =IF($C12="","",VLOOKUP($E12,'📊 SECCIONES'!$B$4:$S$9,8,FALSE())) -> 17450 | R12: =IF($C12="","",VLOOKUP($E12,'📊 SECCIONES'!$B$4:$S$9,10,FALSE())) -> 10.6 | S12: =IF('📇 INVENTARIO'!K13="","",'📇 INVENTARIO'!K13) -> 3 | T12: =IF($C12="","","Objetivo: alcanzar calificación C. Actual: Cal."&F12&". "&IF(OR(F12="G",F12="F"),"SATE integral + cubierta + carpinterías triple + aerotermia + instalación fotovoltaica",IF(F12="E","SATE fachada + carpinterías doble + instalación fotovoltaica",IF(F12="D","Mantenimiento de envolvente + instalación fotovoltaica en cubierta","Optimización energética + instalación fotovoltaica")))) -> Objetivo: alcanzar calificación C. Actual: Cal.G. SATE integral + cubierta + carpinterías triple + aerotermia + instalación fotovoltaica | U12: =IF($C12="","",IF(S12=0,"s/d",IF(S12>=4,"Valorar ascensor (verificar)","—"))) -> — | V12: =IF('📇 INVENTARIO'!L13="","",'📇 INVENTARIO'!L13) -> 95.5 | W12: =IF($C12="","",V12*'⚙️ SUPUESTOS'!$C$8*'⚙️ SUPUESTOS'!$C$9) -> 20.055 | X12: =IF('📇 INVENTARIO'!N13="","",'📇 INVENTARIO'!N13) -> 1431 | Y12: =IF($C12="","",W12*X12*'⚙️ SUPUESTOS'!$C$7) -> 25828.834 | Z12: =IF($C12="","",W12*'⚙️ SUPUESTOS'!$C$10) -> 26773.425 | AA12: =IF($C12="","",Y12*('⚙️ SUPUESTOS'!$C$12*'⚙️ SUPUESTOS'!$C$11+(1-'⚙️ SUPUESTOS'!$C$12)*'⚙️ SUPUESTOS'!$C$13)) -> 1761.5265 | AB12: =IF($C12="","",IF(Y12>0,ROUND(Y12*'⚙️ SUPUESTOS'!$C$12*'⚙️ SUPUESTOS'!$C$11,0),"")) -> 646 | AC12: =IF($C12="","",IF(Y12>0,ROUND(Y12*(1-'⚙️ SUPUESTOS'!$C$12)*'⚙️ SUPUESTOS'!$C$13,0),"")) -> 1116 | AD12: =IF($C12="","",IF(AND(ISNUMBER(AA12),ISNUMBER(AE12),AA12>0,AE12>0),ROUND(AA12*MAX(0,25-AE12),0),"")) -> 17265 | AE12: =IF($C12="","",IF(AA12>0,Z12/AA12,"")) -> 15.198991 | AF12: =IF($C12="","",IF(AE12="","—",IF(AE12<='⚙️ SUPUESTOS'!$C$32,"✔ Muy recomendable",IF(AE12<='⚙️ SUPUESTOS'!$C$33,"✔ Recomendable","Valorar")))) -> ✔ Recomendable | AG12: =IF('📇 INVENTARIO'!O13="","",'📇 INVENTARIO'!O13) -> 41.64887 | AH12: =IF('📇 INVENTARIO'!P13="","",'📇 INVENTARIO'!P13) -> -4.71047
A13: =IF($C13="","",RANK(O13,$O$3:$O$265,0)+COUNTIF($O$3:O13,O13)-1) -> 11 | B13: =IF($C13="","",IF(A13<='⚙️ SUPUESTOS'!$C$29,"Fase 1",IF(A13<='⚙️ SUPUESTOS'!$C$30,"Fase 2","Fase 3"))) -> Fase 1 | C13: =IF('📇 INVENTARIO'!B14="","",'📇 INVENTARIO'!B14) -> C/ Papagayo, 6 | D13: =IF('📇 INVENTARIO'!C14="","",'📇 INVENTARIO'!C14) -> 7825411UM5172F | E13: =IF('📇 INVENTARIO'!D14="","",'📇 INVENTARIO'!D14) -> 4718606023 | F13: =IF('📇 INVENTARIO'!F14="","",'📇 INVENTARIO'!F14) -> G | G13: =IF('📇 INVENTARIO'!G14="","",'📇 INVENTARIO'!G14) -> 589 | H13: =IF('📇 INVENTARIO'!H14="","",'📇 INVENTARIO'!H14) -> 100 | I13: =IF('📇 INVENTARIO'!I14="","",'📇 INVENTARIO'!I14) -> 242.3 | J13: =IF('📇 INVENTARIO'!J14="","",'📇 INVENTARIO'!J14) -> 1965 | K13: =IF($C13="","",(G13-'⚙️ SUPUESTOS'!$C$20)/('⚙️ SUPUESTOS'!$C$25-'⚙️ SUPUESTOS'!$C$20)) -> 0.767642 | L13: =IF($C13="","",VLOOKUP($E13,'📊 SECCIONES'!$B$4:$S$9,16,FALSE())) -> 0.54128061 | M13: =IF($C13="","",VLOOKUP($E13,'📊 SECCIONES'!$B$4:$S$9,17,FALSE())) -> 0.59585492 | N13: =IF($C13="","",VLOOKUP($E13,'📊 SECCIONES'!$B$4:$S$9,18,FALSE())) -> 0.28636364 | O13: =IF($C13="","",ROUND('⚙️ SUPUESTOS'!$C$21*K13+'⚙️ SUPUESTOS'!$C$22*L13+'⚙️ SUPUESTOS'!$C$23*M13+'⚙️ SUPUESTOS'!$C$24*N13,4)) -> 0.6505 | P13: =IF($C13="","",VLOOKUP($E13,'📊 SECCIONES'!$B$4:$S$9,7,FALSE())) -> 39.41 | Q13: =IF($C13="","",VLOOKUP($E13,'📊 SECCIONES'!$B$4:$S$9,8,FALSE())) -> 22486 | R13: =IF($C13="","",VLOOKUP($E13,'📊 SECCIONES'!$B$4:$S$9,10,FALSE())) -> 16.9 | S13: =IF('📇 INVENTARIO'!K14="","",'📇 INVENTARIO'!K14) -> 3 | T13: =IF($C13="","","Objetivo: alcanzar calificación C. Actual: Cal."&F13&". "&IF(OR(F13="G",F13="F"),"SATE integral + cubierta + carpinterías triple + aerotermia + instalación fotovoltaica",IF(F13="E","SATE fachada + carpinterías doble + instalación fotovoltaica",IF(F13="D","Mantenimiento de envolvente + instalación fotovoltaica en cubierta","Optimización energética + instalación fotovoltaica")))) -> Objetivo: alcanzar calificación C. Actual: Cal.G. SATE integral + cubierta + carpinterías triple + aerotermia + instalación fotovoltaica | U13: =IF($C13="","",IF(S13=0,"s/d",IF(S13>=4,"Valorar ascensor (verificar)","—"))) -> — | V13: =IF('📇 INVENTARIO'!L14="","",'📇 INVENTARIO'!L14) -> 100.8 | W13: =IF($C13="","",V13*'⚙️ SUPUESTOS'!$C$8*'⚙️ SUPUESTOS'!$C$9) -> 21.168 | X13: =IF('📇 INVENTARIO'!N14="","",'📇 INVENTARIO'!N14) -> 1399 | Y13: =IF($C13="","",W13*X13*'⚙️ SUPUESTOS'!$C$7) -> 26652.629 | Z13: =IF($C13="","",W13*'⚙️ SUPUESTOS'!$C$10) -> 28259.28 | AA13: =IF($C13="","",Y13*('⚙️ SUPUESTOS'!$C$12*'⚙️ SUPUESTOS'!$C$11+(1-'⚙️ SUPUESTOS'!$C$12)*'⚙️ SUPUESTOS'!$C$13)) -> 1817.7093 | AB13: =IF($C13="","",IF(Y13>0,ROUND(Y13*'⚙️ SUPUESTOS'!$C$12*'⚙️ SUPUESTOS'!$C$11,0),"")) -> 666 | AC13: =IF($C13="","",IF(Y13>0,ROUND(Y13*(1-'⚙️ SUPUESTOS'!$C$12)*'⚙️ SUPUESTOS'!$C$13,0),"")) -> 1151 | AD13: =IF($C13="","",IF(AND(ISNUMBER(AA13),ISNUMBER(AE13),AA13>0,AE13>0),ROUND(AA13*MAX(0,25-AE13),0),"")) -> 17183 | AE13: =IF($C13="","",IF(AA13>0,Z13/AA13,"")) -> 15.546644 | AF13: =IF($C13="","",IF(AE13="","—",IF(AE13<='⚙️ SUPUESTOS'!$C$32,"✔ Muy recomendable",IF(AE13<='⚙️ SUPUESTOS'!$C$33,"✔ Recomendable","Valorar")))) -> ✔ Recomendable | AG13: =IF('📇 INVENTARIO'!O14="","",'📇 INVENTARIO'!O14) -> 41.64956 | AH13: =IF('📇 INVENTARIO'!P14="","",'📇 INVENTARIO'!P14) -> -4.70818
A14: =IF($C14="","",RANK(O14,$O$3:$O$265,0)+COUNTIF($O$3:O14,O14)-1) -> 12 | B14: =IF($C14="","",IF(A14<='⚙️ SUPUESTOS'!$C$29,"Fase 1",IF(A14<='⚙️ SUPUESTOS'!$C$30,"Fase 2","Fase 3"))) -> Fase 1 | C14: =IF('📇 INVENTARIO'!B15="","",'📇 INVENTARIO'!B15) -> C/ Villabáñez, 18 | D14: =IF('📇 INVENTARIO'!C15="","",'📇 INVENTARIO'!C15) -> 7824502UM5172D | E14: =IF('📇 INVENTARIO'!D15="","",'📇 INVENTARIO'!D15) -> 4718606026 | F14: =IF('📇 INVENTARIO'!F15="","",'📇 INVENTARIO'!F15) -> G | G14: =IF('📇 INVENTARIO'!G15="","",'📇 INVENTARIO'!G15) -> 442 | H14: =IF('📇 INVENTARIO'!H15="","",'📇 INVENTARIO'!H15) -> 93 | I14: =IF('📇 INVENTARIO'!I15="","",'📇 INVENTARIO'!I15) -> 200 | J14: =IF('📇 INVENTARIO'!J15="","",'📇 INVENTARIO'!J15) -> 1965 | K14: =IF($C14="","",(G14-'⚙️ SUPUESTOS'!$C$20)/('⚙️ SUPUESTOS'!$C$25-'⚙️ SUPUESTOS'!$C$20)) -> 0.51462995 | L14: =IF($C14="","",VLOOKUP($E14,'📊 SECCIONES'!$B$4:$S$9,16,FALSE())) -> 1 | M14: =IF($C14="","",VLOOKUP($E14,'📊 SECCIONES'!$B$4:$S$9,17,FALSE())) -> 1 | N14: =IF($C14="","",VLOOKUP($E14,'📊 SECCIONES'!$B$4:$S$9,18,FALSE())) -> 0 | O14: =IF($C14="","",ROUND('⚙️ SUPUESTOS'!$C$21*K14+'⚙️ SUPUESTOS'!$C$22*L14+'⚙️ SUPUESTOS'!$C$23*M14+'⚙️ SUPUESTOS'!$C$24*N14,4)) -> 0.643 | P14: =IF($C14="","",VLOOKUP($E14,'📊 SECCIONES'!$B$4:$S$9,7,FALSE())) -> 66.51 | Q14: =IF($C14="","",VLOOKUP($E14,'📊 SECCIONES'!$B$4:$S$9,8,FALSE())) -> 17450 | R14: =IF($C14="","",VLOOKUP($E14,'📊 SECCIONES'!$B$4:$S$9,10,FALSE())) -> 10.6 | S14: =IF('📇 INVENTARIO'!K15="","",'📇 INVENTARIO'!K15) -> 3 | T14: =IF($C14="","","Objetivo: alcanzar calificación C. Actual: Cal."&F14&". "&IF(OR(F14="G",F14="F"),"SATE integral + cubierta + carpinterías triple + aerotermia + instalación fotovoltaica",IF(F14="E","SATE fachada + carpinterías doble + instalación fotovoltaica",IF(F14="D","Mantenimiento de envolvente + instalación fotovoltaica en cubierta","Optimización energética + instalación fotovoltaica")))) -> Objetivo: alcanzar calificación C. Actual: Cal.G. SATE integral + cubierta + carpinterías triple + aerotermia + instalación fotovoltaica | U14: =IF($C14="","",IF(S14=0,"s/d",IF(S14>=4,"Valorar ascensor (verificar)","—"))) -> — | V14: =IF('📇 INVENTARIO'!L15="","",'📇 INVENTARIO'!L15) -> 113.4 | W14: =IF($C14="","",V14*'⚙️ SUPUESTOS'!$C$8*'⚙️ SUPUESTOS'!$C$9) -> 23.814 | X14: =IF('📇 INVENTARIO'!N15="","",'📇 INVENTARIO'!N15) -> 1421 | Y14: =IF($C14="","",W14*X14*'⚙️ SUPUESTOS'!$C$7) -> 30455.725 | Z14: =IF($C14="","",W14*'⚙️ SUPUESTOS'!$C$10) -> 31791.69 | AA14: =IF($C14="","",Y14*('⚙️ SUPUESTOS'!$C$12*'⚙️ SUPUESTOS'!$C$11+(1-'⚙️ SUPUESTOS'!$C$12)*'⚙️ SUPUESTOS'!$C$13)) -> 2077.0804 | AB14: =IF($C14="","",IF(Y14>0,ROUND(Y14*'⚙️ SUPUESTOS'!$C$12*'⚙️ SUPUESTOS'!$C$11,0),"")) -> 761 | AC14: =IF($C14="","",IF(Y14>0,ROUND(Y14*(1-'⚙️ SUPUESTOS'!$C$12)*'⚙️ SUPUESTOS'!$C$13,0),"")) -> 1316 | AD14: =IF($C14="","",IF(AND(ISNUMBER(AA14),ISNUMBER(AE14),AA14>0,AE14>0),ROUND(AA14*MAX(0,25-AE14),0),"")) -> 20135 | AE14: =IF($C14="","",IF(AA14>0,Z14/AA14,"")) -> 15.30595 | AF14: =IF($C14="","",IF(AE14="","—",IF(AE14<='⚙️ SUPUESTOS'!$C$32,"✔ Muy recomendable",IF(AE14<='⚙️ SUPUESTOS'!$C$33,"✔ Recomendable","Valorar")))) -> ✔ Recomendable | AG14: =IF('📇 INVENTARIO'!O15="","",'📇 INVENTARIO'!O15) -> 41.64896 | AH14: =IF('📇 INVENTARIO'!P15="","",'📇 INVENTARIO'!P15) -> -4.70864
A15: =IF($C15="","",RANK(O15,$O$3:$O$265,0)+COUNTIF($O$3:O15,O15)-1) -> 13 | B15: =IF($C15="","",IF(A15<='⚙️ SUPUESTOS'!$C$29,"Fase 1",IF(A15<='⚙️ SUPUESTOS'!$C$30,"Fase 2","Fase 3"))) -> Fase 1 | C15: =IF('📇 INVENTARIO'!B16="","",'📇 INVENTARIO'!B16) -> C/ Cuclillo, 3 | D15: =IF('📇 INVENTARIO'!C16="","",'📇 INVENTARIO'!C16) -> 7724216UM5172D | E15: =IF('📇 INVENTARIO'!D16="","",'📇 INVENTARIO'!D16) -> 4718606026 | F15: =IF('📇 INVENTARIO'!F16="","",'📇 INVENTARIO'!F16) -> G | G15: =IF('📇 INVENTARIO'!G16="","",'📇 INVENTARIO'!G16) -> 442 | H15: =IF('📇 INVENTARIO'!H16="","",'📇 INVENTARIO'!H16) -> 88 | I15: =IF('📇 INVENTARIO'!I16="","",'📇 INVENTARIO'!I16) -> 223.4 | J15: =IF('📇 INVENTARIO'!J16="","",'📇 INVENTARIO'!J16) -> 1965 | K15: =IF($C15="","",(G15-'⚙️ SUPUESTOS'!$C$20)/('⚙️ SUPUESTOS'!$C$25-'⚙️ SUPUESTOS'!$C$20)) -> 0.51462995 | L15: =IF($C15="","",VLOOKUP($E15,'📊 SECCIONES'!$B$4:$S$9,16,FALSE())) -> 1 | M15: =IF($C15="","",VLOOKUP($E15,'📊 SECCIONES'!$B$4:$S$9,17,FALSE())) -> 1 | N15: =IF($C15="","",VLOOKUP($E15,'📊 SECCIONES'!$B$4:$S$9,18,FALSE())) -> 0 | O15: =IF($C15="","",ROUND('⚙️ SUPUESTOS'!$C$21*K15+'⚙️ SUPUESTOS'!$C$22*L15+'⚙️ SUPUESTOS'!$C$23*M15+'⚙️ SUPUESTOS'!$C$24*N15,4)) -> 0.643 | P15: =IF($C15="","",VLOOKUP($E15,'📊 SECCIONES'!$B$4:$S$9,7,FALSE())) -> 66.51 | Q15: =IF($C15="","",VLOOKUP($E15,'📊 SECCIONES'!$B$4:$S$9,8,FALSE())) -> 17450 | R15: =IF($C15="","",VLOOKUP($E15,'📊 SECCIONES'!$B$4:$S$9,10,FALSE())) -> 10.6 | S15: =IF('📇 INVENTARIO'!K16="","",'📇 INVENTARIO'!K16) -> 3 | T15: =IF($C15="","","Objetivo: alcanzar calificación C. Actual: Cal."&F15&". "&IF(OR(F15="G",F15="F"),"SATE integral + cubierta + carpinterías triple + aerotermia + instalación fotovoltaica",IF(F15="E","SATE fachada + carpinterías doble + instalación fotovoltaica",IF(F15="D","Mantenimiento de envolvente + instalación fotovoltaica en cubierta","Optimización energética + instalación fotovoltaica")))) -> Objetivo: alcanzar calificación C. Actual: Cal.G. SATE integral + cubierta + carpinterías triple + aerotermia + instalación fotovoltaica | U15: =IF($C15="","",IF(S15=0,"s/d",IF(S15>=4,"Valorar ascensor (verificar)","—"))) -> — | V15: =IF('📇 INVENTARIO'!L16="","",'📇 INVENTARIO'!L16) -> 104.6 | W15: =IF($C15="","",V15*'⚙️ SUPUESTOS'!$C$8*'⚙️ SUPUESTOS'!$C$9) -> 21.966 | X15: =IF('📇 INVENTARIO'!N16="","",'📇 INVENTARIO'!N16) -> 1328 | Y15: =IF($C15="","",W15*X15*'⚙️ SUPUESTOS'!$C$7) -> 26253.763 | Z15: =IF($C15="","",W15*'⚙️ SUPUESTOS'!$C$10) -> 29324.61 | AA15: =IF($C15="","",Y15*('⚙️ SUPUESTOS'!$C$12*'⚙️ SUPUESTOS'!$C$11+(1-'⚙️ SUPUESTOS'!$C$12)*'⚙️ SUPUESTOS'!$C$13)) -> 1790.5067 | AB15: =IF($C15="","",IF(Y15>0,ROUND(Y15*'⚙️ SUPUESTOS'!$C$12*'⚙️ SUPUESTOS'!$C$11,0),"")) -> 656 | AC15: =IF($C15="","",IF(Y15>0,ROUND(Y15*(1-'⚙️ SUPUESTOS'!$C$12)*'⚙️ SUPUESTOS'!$C$13,0),"")) -> 1134 | AD15: =IF($C15="","",IF(AND(ISNUMBER(AA15),ISNUMBER(AE15),AA15>0,AE15>0),ROUND(AA15*MAX(0,25-AE15),0),"")) -> 15438 | AE15: =IF($C15="","",IF(AA15>0,Z15/AA15,"")) -> 16.377828 | AF15: =IF($C15="","",IF(AE15="","—",IF(AE15<='⚙️ SUPUESTOS'!$C$32,"✔ Muy recomendable",IF(AE15<='⚙️ SUPUESTOS'!$C$33,"✔ Recomendable","Valorar")))) -> Valorar | AG15: =IF('📇 INVENTARIO'!O16="","",'📇 INVENTARIO'!O16) -> 41.648759 | AH15: =IF('📇 INVENTARIO'!P16="","",'📇 INVENTARIO'!P16) -> -4.709681
A16: =IF($C16="","",RANK(O16,$O$3:$O$265,0)+COUNTIF($O$3:O16,O16)-1) -> 14 | B16: =IF($C16="","",IF(A16<='⚙️ SUPUESTOS'!$C$29,"Fase 1",IF(A16<='⚙️ SUPUESTOS'!$C$30,"Fase 2","Fase 3"))) -> Fase 1 | C16: =IF('📇 INVENTARIO'!B17="","",'📇 INVENTARIO'!B17) -> C/ Águila, 21 | D16: =IF('📇 INVENTARIO'!C17="","",'📇 INVENTARIO'!C17) -> 7724217UM5172D | E16: =IF('📇 INVENTARIO'!D17="","",'📇 INVENTARIO'!D17) -> 4718606026 | F16: =IF('📇 INVENTARIO'!F17="","",'📇 INVENTARIO'!F17) -> E | G16: =IF('📇 INVENTARIO'!G17="","",'📇 INVENTARIO'!G17) -> 442 | H16: =IF('📇 INVENTARIO'!H17="","",'📇 INVENTARIO'!H17) -> 92.5 | I16: =IF('📇 INVENTARIO'!I17="","",'📇 INVENTARIO'!I17) -> 203.3 | J16: =IF('📇 INVENTARIO'!J17="","",'📇 INVENTARIO'!J17) -> 1965 | K16: =IF($C16="","",(G16-'⚙️ SUPUESTOS'!$C$20)/('⚙️ SUPUESTOS'!$C$25-'⚙️ SUPUESTOS'!$C$20)) -> 0.51462995 | L16: =IF($C16="","",VLOOKUP($E16,'📊 SECCIONES'!$B$4:$S$9,16,FALSE())) -> 1 | M16: =IF($C16="","",VLOOKUP($E16,'📊 SECCIONES'!$B$4:$S$9,17,FALSE())) -> 1 | N16: =IF($C16="","",VLOOKUP($E16,'📊 SECCIONES'!$B$4:$S$9,18,FALSE())) -> 0 | O16: =IF($C16="","",ROUND('⚙️ SUPUESTOS'!$C$21*K16+'⚙️ SUPUESTOS'!$C$22*L16+'⚙️ SUPUESTOS'!$C$23*M16+'⚙️ SUPUESTOS'!$C$24*N16,4)) -> 0.643 | P16: =IF($C16="","",VLOOKUP($E16,'📊 SECCIONES'!$B$4:$S$9,7,FALSE())) -> 66.51 | Q16: =IF($C16="","",VLOOKUP($E16,'📊 SECCIONES'!$B$4:$S$9,8,FALSE())) -> 17450 | R16: =IF($C16="","",VLOOKUP($E16,'📊 SECCIONES'!$B$4:$S$9,10,FALSE())) -> 10.6 | S16: =IF('📇 INVENTARIO'!K17="","",'📇 INVENTARIO'!K17) -> 3 | T16: =IF($C16="","","Objetivo: alcanzar calificación C. Actual: Cal."&F16&". "&IF(OR(F16="G",F16="F"),"SATE integral + cubierta + carpinterías triple + aerotermia + instalación fotovoltaica",IF(F16="E","SATE fachada + carpinterías doble + instalación fotovoltaica",IF(F16="D","Mantenimiento de envolvente + instalación fotovoltaica en cubierta","Optimización energética + instalación fotovoltaica")))) -> Objetivo: alcanzar calificación C. Actual: Cal.E. SATE fachada + carpinterías doble + instalación fotovoltaica | U16: =IF($C16="","",IF(S16=0,"s/d",IF(S16>=4,"Valorar ascensor (verificar)","—"))) -> — | V16: =IF('📇 INVENTARIO'!L17="","",'📇 INVENTARIO'!L17) -> 98.1 | W16: =IF($C16="","",V16*'⚙️ SUPUESTOS'!$C$8*'⚙️ SUPUESTOS'!$C$9) -> 20.601 | X16: =IF('📇 INVENTARIO'!N17="","",'📇 INVENTARIO'!N17) -> 1396 | Y16: =IF($C16="","",W16*X16*'⚙️ SUPUESTOS'!$C$7) -> 25883.096 | Z16: =IF($C16="","",W16*'⚙️ SUPUESTOS'!$C$10) -> 27502.335 | AA16: =IF($C16="","",Y16*('⚙️ SUPUESTOS'!$C$12*'⚙️ SUPUESTOS'!$C$11+(1-'⚙️ SUPUESTOS'!$C$12)*'⚙️ SUPUESTOS'!$C$13)) -> 1765.2272 | AB16: =IF($C16="","",IF(Y16>0,ROUND(Y16*'⚙️ SUPUESTOS'!$C$12*'⚙️ SUPUESTOS'!$C$11,0),"")) -> 647 | AC16: =IF($C16="","",IF(Y16>0,ROUND(Y16*(1-'⚙️ SUPUESTOS'!$C$12)*'⚙️ SUPUESTOS'!$C$13,0),"")) -> 1118 | AD16: =IF($C16="","",IF(AND(ISNUMBER(AA16),ISNUMBER(AE16),AA16>0,AE16>0),ROUND(AA16*MAX(0,25-AE16),0),"")) -> 16628 | AE16: =IF($C16="","",IF(AA16>0,Z16/AA16,"")) -> 15.580054 | AF16: =IF($C16="","",IF(AE16="","—",IF(AE16<='⚙️ SUPUESTOS'!$C$32,"✔ Muy recomendable",IF(AE16<='⚙️ SUPUESTOS'!$C$33,"✔ Recomendable","Valorar")))) -> ✔ Recomendable | AG16: =IF('📇 INVENTARIO'!O17="","",'📇 INVENTARIO'!O17) -> 41.64858 | AH16: =IF('📇 INVENTARIO'!P17="","",'📇 INVENTARIO'!P17) -> -4.70948
